package com.scarlet.coroutines.exceptions

import com.scarlet.util.log
import com.scarlet.util.onCompletion
import kotlinx.coroutines.*
import kotlinx.coroutines.test.runTest
import org.junit.Test

@ExperimentalCoroutinesApi
class CancellationTest {

    private suspend fun networkRequestCooperative() {
        log("networkRequestDelayed")
        delay(1_000)
        log("networkRequestDelayed done")
    }

    private suspend fun networkRequestFailed() {
        log("networkRequestFailed")
        delay(1_000)
        log("throwing exception from networkFailedRequest")
        throw RuntimeException("Oops...from networkFailedRequest")
    }

    private suspend fun networkRequestUncooperative() = coroutineScope {
        log("networkRequestUncooperative")
        log("fib(45) = ${fib(45)}")
        log("networkRequestUncooperative done")
    }

    private fun fib(n: Long): Long = if (n <= 1) n else fib(n - 1) + fib(n - 2)

    /**/

    @Test
    fun `uncooperative coroutine cannot be cancelled`() = runTest {
        val job = launch {
            networkRequestUncooperative()
        }.onCompletion("job")

        delay(100)

        job.cancelAndJoin()
    }

    @Test
    fun `cooperative coroutine can be canceled`() = runTest {
        val job = launch {
            networkRequestCooperative()
        }.onCompletion("job")

        delay(100)

        job.cancelAndJoin()
    }

    @Test
    fun `failed suspending function throws causing exception, not cancellation exception`() = runTest {
        launch {
            try {
                networkRequestFailed()
            } catch(ex: Exception) {
                log("Caught exception = $ex")
            }
        }
    }

    /**
     * Check to see what happens when coroutine is cancelled
     *
     * Cancelled coroutine sets its status as `Cancelling`, and executes
     * rest of the computation (probably call cancel() to child coroutines if exist).
     * If `Cancellation` exception is thrown from any computation, it skips
     * the rest of the computation immediately!!!!!!!!!!!!!!!!!!!!!!
     */

    // DO NOT CATCH CANCELLATION EXCEPTION!! IF YOU HAPPEN TO CATCH IT, RETHROW IT!!
    @Test
    fun `cancellation exception swallowed - so, next suspend function starts running`() = runTest {
        val job = launch {
            log("Coroutine starts running ... isActive = ${(coroutineContext.isActive)}")

            try {
                networkRequestCooperative()
            } catch (ex: Exception) {
                log("Caught: ${ex.javaClass.simpleName}")
            }

            log("Coroutine keep running ... isActive = ${(coroutineContext.isActive)}")
            networkRequestUncooperative() // this will not be skipped
        }.onCompletion("job")

        delay(100)
        job.cancelAndJoin()
    }

    @Test
    fun `cancellation caught, but rethrown - remaining computation all skipped`() = runTest {

        val job = launch {
            try {
                networkRequestCooperative()
            } catch (ex: Exception) {
                log("Caught: ${ex.javaClass.simpleName}")
                if (ex is CancellationException) {
                    throw ex
                }
            }

            log("All subsequent computations will be skipped ...")
            networkRequestUncooperative() // long running computation
            log("This will not be printed")

        }.onCompletion("job")

        delay(100)

        job.cancelAndJoin()
    }

}